Workbook

Sheet KeyData
A1: ID | B1: Area | C1: shape | D1: size(W*D*H) | E1: cm^3 | F1: Supplement
A2: 17 | B2: พื้นที่ศาลา | C2: รังขนาดA4 | D2: 21.5*40*7 | E2: =21.5*40*7 -> 6020 | F2: อาหารเสริม
A3: 18 | B3: พื้นที่ศาลา | C3: รังขนาดA4 | D3: 24.5*38.5*7 | E3: =24.5*38.5*7 -> 6602.75 | F3: ไม่ใช้อาหารเสริม
A4: 44 | B4: พื้นที่ศาลา | C4: รังทรงสูง | D4: 17*27.5*11.5 | E4: =17*27.5*11.5 -> 5376.25 | F4: ไม่ใช้อาหารเสริม
A5: 45 | B5: พื้นที่ศาลา | C5: รังทรงสูง | D5: 16*27*11 | E5: =16*27*11 -> 4752 | F5: อาหารเสริม
A6: 16 | B6: พื้นที่ศาลา | C6: รังขนาดA4 | D6: 21.5*40.5*7 | E6: =21.5*40.5*7 -> 6095.25 | F6: อาหารเสริม

Sheet Tracking
A1: week | B1: Date | C1: weather | D1: Timeframe
A2: 1 | B2: 45826 | C2: แจ่มใส | D2: late morning
A3: 2 | B3: 45833 | C3: แจ่มใส | D3: late morning
A4: 3 | B4: 45840 | C4: ลมแรงเมฆมาก | D4: late morning
A5: 4 | B5: 45847 | C5: ลมแรงเมฆมาก | D5: late morning
A6: 5 | B6: 45854 | C6: ลมแรงเมฆมาก | D6: late morning
A7: 6 | B7: 45861 | C7: แจ่มใส | D7: late morning
A8: 7 | B8: 45868 | C8: แจ่มใส | D8: late morning
A9: 8 | B9: 45875 | C9: แจ่มใส | D9: late morning
A10: 9 | B10: 45882 | C10: ลมแรงเมฆมาก | D10: late morning
A11: 9 | B11: 45882 | C11: แจ่มใส | D11: late morning | E11: 45883
A12: 10 | B12: 45889 | C12: แจ่มใส | D12: late morning
A13: 11 | B13: 45896 | C13: ลมแรงเมฆมาก | D13: late morning
A14: 12 | B14: 45903 | C14: แจ่มใส | D14: late morning
A15: 13 | B15: 45910 | C15: แจ่มใส | D15: late morning

Sheet Hive
A1: ID | B1: Week | C1: Date | D1: weather | E1: Weight | F1: Enter | G1: Exit | H1: Area | I1: shape | J1: Supplement
A2: =KeyData!A2 -> 17 | B2: =Tracking!A2 -> 1 | C2: =Tracking!B2 -> 45826 | D2: =Tracking!C2 -> แจ่มใส | E2: 3.71 | F2: 36 | G2: 27 | H2: =KeyData!B2 -> พื้นที่ศาลา | I2: =KeyData!C2 -> รังขนาดA4 | J2: =KeyData!F2 -> อาหารเสริม
A3: =KeyData!A3 -> 18 | B3: =Tracking!A2 -> 1 | C3: =Tracking!B2 -> 45826 | D3: =Tracking!C2 -> แจ่มใส | E3: 4.12 | F3: 30 | G3: 31 | H3: =KeyData!B3 -> พื้นที่ศาลา | I3: =KeyData!C3 -> รังขนาดA4 | J3: =KeyData!F3 -> ไม่ใช้อาหารเสริม
A4: =KeyData!A4 -> 44 | B4: =Tracking!A2 -> 1 | C4: =Tracking!B2 -> 45826 | D4: =Tracking!C2 -> แจ่มใส | E4: 3.27 | F4: 42 | G4: 51 | H4: =KeyData!B4 -> พื้นที่ศาลา | I4: =KeyData!C4 -> รังทรงสูง | J4: =KeyData!F4 -> ไม่ใช้อาหารเสริม
A5: =KeyData!A5 -> 45 | B5: =Tracking!A2 -> 1 | C5: =Tracking!B2 -> 45826 | D5: =Tracking!C2 -> แจ่มใส | E5: 2.62 | F5: 109 | G5: 62 | H5: =KeyData!B5 -> พื้นที่ศาลา | I5: =KeyData!C5 -> รังทรงสูง | J5: =KeyData!F5 -> อาหารเสริม
A6: =A2 -> 17 | B6: =Tracking!A3 -> 2 | C6: =Tracking!B3 -> 45833 | D6: =Tracking!C3 -> แจ่มใส | E6: 3.71 | F6: 31 | G6: 24 | H6: =$H$2 -> พื้นที่ศาลา | I6: =$I$2 -> รังขนาดA4 | J6: =$J$2 -> อาหารเสริม
A7: =A3 -> 18 | B7: =Tracking!A3 -> 2 | C7: =Tracking!B3 -> 45833 | D7: =Tracking!C3 -> แจ่มใส | E7: 4.11 | F7: 60 | G7: 75 | H7: =$H$3 -> พื้นที่ศาลา | I7: =$I$3 -> รังขนาดA4 | J7: =$J$3 -> ไม่ใช้อาหารเสริม
A8: =A4 -> 44 | B8: =Tracking!A3 -> 2 | C8: =Tracking!B3 -> 45833 | D8: =Tracking!C3 -> แจ่มใส | E8: 3.28 | F8: 29 | G8: 41 | H8: =$H$4 -> พื้นที่ศาลา | I8: =$I$4 -> รังทรงสูง | J8: =$J$4 -> ไม่ใช้อาหารเสริม
A9: =A5 -> 45 | B9: =Tracking!A3 -> 2 | C9: =Tracking!B3 -> 45833 | D9: =Tracking!C3 -> แจ่มใส | E9: 2.63 | F9: 36 | G9: 33 | H9: =$H$5 -> พื้นที่ศาลา | I9: =$I$5 -> รังทรงสูง | J9: =$J$5 -> อาหารเสริม
A10: =A6 -> 17 | B10: =Tracking!A4 -> 3 | C10: =Tracking!B4 -> 45840 | D10: =Tracking!C4 -> ลมแรงเมฆมาก | E10: 3.7 | F10: 7 | G10: 4 | H10: =$H$2 -> พื้นที่ศาลา | I10: =$I$2 -> รังขนาดA4 | J10: =$J$2 -> อาหารเสริม
A11: =A7 -> 18 | B11: =Tracking!A4 -> 3 | C11: =Tracking!B4 -> 45840 | D11: =Tracking!C4 -> ลมแรงเมฆมาก | E11: 4.08 | F11: 43 | G11: 16 | H11: =$H$3 -> พื้นที่ศาลา | I11: =$I$3 -> รังขนาดA4 | J11: =$J$3 -> ไม่ใช้อาหารเสริม
A12: =A8 -> 44 | B12: =Tracking!A4 -> 3 | C12: =Tracking!B4 -> 45840 | D12: =Tracking!C4 -> ลมแรงเมฆมาก | E12: 3.27 | F12: 40 | G12: 36 | H12: =$H$4 -> พื้นที่ศาลา | I12: =$I$4 -> รังทรงสูง | J12: =$J$4 -> ไม่ใช้อาหารเสริม
A13: =A9 -> 45 | B13: =Tracking!A4 -> 3 | C13: =Tracking!B4 -> 45840 | D13: =Tracking!C4 -> ลมแรงเมฆมาก | E13: 2.62 | F13: 56 | G13: 77 | H13: =$H$5 -> พื้นที่ศาลา | I13: =$I$5 -> รังทรงสูง | J13: =$J$5 -> อาหารเสริม
A14: =A10 -> 17 | B14: =Tracking!A5 -> 4 | C14: =Tracking!B5 -> 45847 | D14: =Tracking!C5 -> ลมแรงเมฆมาก | E14: 3.7 | F14: 8 | G14: 11 | H14: =$H$2 -> พื้นที่ศาลา | I14: =$I$2 -> รังขนาดA4 | J14: =$J$2 -> อาหารเสริม
A15: =A11 -> 18 | B15: =Tracking!A5 -> 4 | C15: =Tracking!B5 -> 45847 | D15: =Tracking!C5 -> ลมแรงเมฆมาก | E15: 4.07 | F15: 10 | G15: 17 | H15: =$H$3 -> พื้นที่ศาลา | I15: =$I$3 -> รังขนาดA4 | J15: =$J$3 -> ไม่ใช้อาหารเสริม
A16: =A12 -> 44 | B16: =Tracking!A5 -> 4 | C16: =Tracking!B5 -> 45847 | D16: =Tracking!C5 -> ลมแรงเมฆมาก | E16: 3.28 | F16: 37 | G16: 35 | H16: =$H$4 -> พื้นที่ศาลา | I16: =$I$4 -> รังทรงสูง | J16: =$J$4 -> ไม่ใช้อาหารเสริม
A17: =A13 -> 45 | B17: =Tracking!A5 -> 4 | C17: =Tracking!B5 -> 45847 | D17: =Tracking!C5 -> ลมแรงเมฆมาก | E17: 2.62 | F17: 85 | G17: 103 | H17: =$H$5 -> พื้นที่ศาลา | I17: =$I$5 -> รังทรงสูง | J17: =$J$5 -> อาหารเสริม
A18: =A14 -> 17 | B18: =Tracking!A6 -> 5 | C18: =Tracking!B6 -> 45854 | D18: =Tracking!C6 -> ลมแรงเมฆมาก | E18: 3.68 | F18: 10 | G18: 1 | H18: =$H$2 -> พื้นที่ศาลา | I18: =$I$2 -> รังขนาดA4 | J18: =$J$2 -> อาหารเสริม
A19: =A15 -> 18 | B19: =Tracking!A6 -> 5 | C19: =Tracking!B6 -> 45854 | D19: =Tracking!C6 -> ลมแรงเมฆมาก | E19: 4.05 | F19: 85 | G19: 33 | H19: =$H$3 -> พื้นที่ศาลา | I19: =$I$3 -> รังขนาดA4 | J19: =$J$3 -> ไม่ใช้อาหารเสริม
A20: =A16 -> 44 | B20: =Tracking!A6 -> 5 | C20: =Tracking!B6 -> 45854 | D20: =Tracking!C6 -> ลมแรงเมฆมาก | E20: 3.26 | F20: 34 | G20: 39 | H20: =$H$4 -> พื้นที่ศาลา | I20: =$I$4 -> รังทรงสูง | J20: =$J$4 -> ไม่ใช้อาหารเสริม
A21: =A17 -> 45 | B21: =Tracking!A6 -> 5 | C21: =Tracking!B6 -> 45854 | D21: =Tracking!C6 -> ลมแรงเมฆมาก | E21: 2.62 | F21: 94 | G21: 88 | H21: =$H$5 -> พื้นที่ศาลา | I21: =$I$5 -> รังทรงสูง | J21: =$J$5 -> อาหารเสริม
A22: =A18 -> 17 | B22: =Tracking!A7 -> 6 | C22: =Tracking!B7 -> 45861 | D22: =Tracking!C7 -> แจ่มใส | E22: 3.69 | F22: 5 | G22: 5 | H22: =$H$2 -> พื้นที่ศาลา | I22: =$I$2 -> รังขนาดA4 | J22: =$J$2 -> อาหารเสริม
A23: =A19 -> 18 | B23: =Tracking!A7 -> 6 | C23: =Tracking!B7 -> 45861 | D23: =Tracking!C7 -> แจ่มใส | E23: 4.04 | F23: 43 | G23: 18 | H23: =$H$3 -> พื้นที่ศาลา | I23: =$I$3 -> รังขนาดA4 | J23: =$J$3 -> ไม่ใช้อาหารเสริม
A24: =A20 -> 44 | B24: =Tracking!A7 -> 6 | C24: =Tracking!B7 -> 45861 | D24: =Tracking!C7 -> แจ่มใส | E24: 3.26 | F24: 40 | G24: 32 | H24: =$H$4 -> พื้นที่ศาลา | I24: =$I$4 -> รังทรงสูง | J24: =$J$4 -> ไม่ใช้อาหารเสริม
A25: =A21 -> 45 | B25: =Tracking!A7 -> 6 | C25: =Tracking!B7 -> 45861 | D25: =Tracking!C7 -> แจ่มใส | E25: 2.62 | F25: 30 | G25: 33 | H25: =$H$2 -> พื้นที่ศาลา | I25: =$I$5 -> รังทรงสูง | J25: =$J$5 -> อาหารเสริม
A26: =A22 -> 17 | B26: =Tracking!A8 -> 7 | C26: =Tracking!B8 -> 45868 | D26: =Tracking!C8 -> แจ่มใส | E26: 3.68 | F26: 5 | G26: 2 | H26: =$H$3 -> พื้นที่ศาลา | I26: =$I$2 -> รังขนาดA4 | J26: =$J$2 -> อาหารเสริม
A27: =A23 -> 18 | B27: =Tracking!A8 -> 7 | C27: =Tracking!B8 -> 45868 | D27: =Tracking!C8 -> แจ่มใส | E27: 4.05 | F27: 9 | G27: 20 | H27: =$H$4 -> พื้นที่ศาลา | I27: =$I$3 -> รังขนาดA4 | J27: =$J$3 -> ไม่ใช้อาหารเสริม
A28: =A24 -> 44 | B28: =Tracking!A8 -> 7 | C28: =Tracking!B8 -> 45868 | D28: =Tracking!C8 -> แจ่มใส | E28: 3.26 | F28: 32 | G28: 31 | H28: =$H$5 -> พื้นที่ศาลา | I28: =$I$4 -> รังทรงสูง | J28: =$J$4 -> ไม่ใช้อาหารเสริม
A29: =A25 -> 45 | B29: =Tracking!A8 -> 7 | C29: =Tracking!B8 -> 45868 | D29: =Tracking!C8 -> แจ่มใส | E29: 2.63 | F29: 23 | G29: 2 | H29: =$H$2 -> พื้นที่ศาลา | I29: =$I$5 -> รังทรงสูง | J29: =$J$5 -> อาหารเสริม
A30: =A26 -> 17 | B30: =Tracking!A9 -> 8 | C30: =Tracking!B9 -> 45875 | D30: =Tracking!C9 -> แจ่มใส | E30: 3.66 | F30: 5 | G30: 4 | H30: =$H$3 -> พื้นที่ศาลา | I30: =$I$3 -> รังขนาดA4 | J30: =$J$2 -> อาหารเสริม
A31: =A27 -> 18 | B31: =Tracking!A9 -> 8 | C31: =Tracking!B9 -> 45875 | D31: =Tracking!C9 -> แจ่มใส | E31: 4.01 | F31: 28 | G31: 16 | H31: =$H$4 -> พื้นที่ศาลา | I31: =$I$3 -> รังขนาดA4 | J31: =$J$3 -> ไม่ใช้อาหารเสริม
A32: =A28 -> 44 | B32: =Tracking!A9 -> 8 | C32: =Tracking!B9 -> 45875 | D32: =Tracking!C9 -> แจ่มใส | E32: 3.23 | F32: 8 | G32: 7 | H32: =$H$5 -> พื้นที่ศาลา | I32: =$I$4 -> รังทรงสูง | J32: =$J$4 -> ไม่ใช้อาหารเสริม
A33: =A29 -> 45 | B33: =Tracking!A9 -> 8 | C33: =Tracking!B9 -> 45875 | D33: =Tracking!C9 -> แจ่มใส | E33: 2.6 | F33: 19 | G33: 15 | H33: =$H$2 -> พื้นที่ศาลา | I33: =$I$5 -> รังทรงสูง | J33: =$J$5 -> อาหารเสริม
A34: =A30 -> 17 | B34: =Tracking!A10 -> 9 | C34: =Tracking!B10 -> 45882 | D34: =Tracking!C10 -> ลมแรงเมฆมาก | E34: 3.65 | F34: 2 | G34: 3 | H34: =$H$3 -> พื้นที่ศาลา | I34: =$I$3 -> รังขนาดA4 | J34: =$J$2 -> อาหารเสริม
A35: =A31 -> 18 | B35: =Tracking!A10 -> 9 | C35: =Tracking!B10 -> 45882 | D35: =Tracking!C10 -> ลมแรงเมฆมาก | E35: 4 | F35: 26 | G35: 30 | H35: =$H$4 -> พื้นที่ศาลา | I35: =$I$2 -> รังขนาดA4 | J35: =$J$3 -> ไม่ใช้อาหารเสริม
A36: =A32 -> 44 | B36: =Tracking!A10 -> 9 | C36: =Tracking!B10 -> 45882 | D36: =Tracking!C10 -> ลมแรงเมฆมาก | E36: 3.23 | F36: 23 | G36: 10 | H36: =$H$5 -> พื้นที่ศาลา | I36: =$I$5 -> รังทรงสูง | J36: =$J$4 -> ไม่ใช้อาหารเสริม
A37: =A33 -> 45 | B37: =Tracking!A10 -> 9 | C37: =Tracking!B10 -> 45882 | D37: =Tracking!C10 -> ลมแรงเมฆมาก | E37: 2.59 | F37: 31 | G37: 26 | H37: =$H$2 -> พื้นที่ศาลา | I37: =$I$5 -> รังทรงสูง | J37: =$J$5 -> อาหารเสริม
A38: =KeyData!A6 -> 16 | B38: =Tracking!A10 -> 9 | C38: =Tracking!B11 -> 45882 | D38: =Tracking!C11 -> แจ่มใส | E38: 3.72 | F38: 78 | G38: 15 | H38: =KeyData!B6 -> พื้นที่ศาลา | I38: =KeyData!C6 -> รังขนาดA4 | J38: =KeyData!F6 -> อาหารเสริม
A39: =$A$38 -> 16 | B39: =Tracking!A12 -> 10 | C39: =Tracking!B12 -> 45889 | D39: =Tracking!C12 -> แจ่มใส | E39: 3.7 | F39: 8 | G39: 44 | H39: =$H$38 -> พื้นที่ศาลา | I39: =$I$38 -> รังขนาดA4 | J39: =$J$2 -> อาหารเสริม
A40: =A35 -> 18 | B40: =Tracking!A12 -> 10 | C40: =Tracking!B12 -> 45889 | D40: =Tracking!C12 -> แจ่มใส | E40: 4.02 | F40: 137 | G40: 110 | H40: =$H$4 -> พื้นที่ศาลา | I40: =$I$38 -> รังขนาดA4 | J40: =$J$3 -> ไม่ใช้อาหารเสริม
...
